Workbook

Sheet Raw Data
A1: trials.thisTrialN | B1: trials.stepSize | C1: trials.intensity | D1: thisRow.t | E1: notes | F1: piloting | G1: Instructions.started | H1: text.started | I1: key_resp_2.started | J1: Instructions.stopped | K1: key_resp_2.keys | L1: key_resp_2.rt | M1: key_resp_2.duration | N1: trial.started | O1: Fixation.started | P1: Fixation.stopped | Q1: grating.started | R1: key_resp.started | S1: grating.stopped | T1: trial.stopped | U1: corrAns | V1: tilt | W1: key_resp.corr | X1: trials.response | Y1: key_resp.rt | Z1: thank_you.started | AA1: text_2.started | AB1: text_2.stopped | AC1: thank_you.stopped | AD1: participant | AE1: session | AF1: date | AG1: expName | AH1: expVersion | AI1: psychopyVersion | AJ1: frameRate | AK1: expStart
F2: =FALSE() -> FALSE | G2: 0.020010542 | H2: 0.036611583 | I2: 0.036611583 | J2: 7.4270472 | K2: space | L2: 7.3752973 | AD2: sc1 | AE2: 1 | AF2: 2026-09-09_01h17.37.730 | AG2: staircase task | AI2: 2026.2.3 | AJ2: 59.761224 | AK2: 2026-09-09 01h17.37.783528 +0530
A3: 0 | B3: 2 | C3: 10 | D3: 7.4361775 | N3: 7.4273273 | O3: 7.4361775 | P3: 8.0028824 | Q3: 8.0028824 | R3: 8.0028824 | S3: 8.3034929 | T3: 9.087677 | U3: left | V3: -10 | W3: 1 | X3: 1 | Y3: 1.0831353 | AD3: sc1 | AE3: 1 | AF3: 2026-09-09_01h17.37.730 | AG3: staircase task | AI3: 2026.2.3 | AJ3: 59.761224 | AK3: 2026-09-09 01h17.37.783528 +0530
A4: 1 | B4: 2 | C4: 8 | D4: 9.104578 | N4: 9.087728 | O4: 9.104578 | P4: 9.6201634 | Q4: 9.5867169 | R4: 9.5867169 | S4: 9.8872449 | T4: 10.070821 | U4: left | V4: -8 | W4: 1 | X4: 1 | Y4: 0.47211892 | AD4: sc1 | AE4: 1 | AF4: 2026-09-09_01h17.37.730 | AG4: staircase task | AI4: 2026.2.3 | AJ4: 59.761224 | AK4: 2026-09-09 01h17.37.783528 +0530
A5: 2 | B5: 2 | C5: 6 | D5: 10.087257 | N5: 10.070866 | O5: 10.087257 | P5: 10.587344 | Q5: 10.570523 | R5: 10.570523 | S5: 10.870695 | T5: 11.086919 | U5: right | V5: 6 | W5: 1 | X5: 1 | Y5: 0.51431433 | AD5: sc1 | AE5: 1 | AF5: 2026-09-09_01h17.37.730 | AG5: staircase task | AI5: 2026.2.3 | AJ5: 59.761224 | AK5: 2026-09-09 01h17.37.783528 +0530
A6: 3 | B6: 2 | C6: 4 | D6: 11.102692 | N6: 11.086976 | O6: 11.102692 | P6: 11.604093 | Q6: 11.587306 | R6: 11.587306 | S6: 11.887392 | T6: 12.104311 | U6: right | V6: 4 | W6: 1 | X6: 1 | Y6: 0.51250846 | AD6: sc1 | AE6: 1 | AF6: 2026-09-09_01h17.37.730 | AG6: staircase task | AI6: 2026.2.3 | AJ6: 59.761224 | AK6: 2026-09-09 01h17.37.783528 +0530
A7: 4 | B7: 2 | C7: 2 | D7: 12.120621 | N7: 12.104353 | O7: 12.120621 | P7: 12.620607 | Q7: 12.603951 | R7: 12.603951 | S7: 12.903898 | T7: 13.087479 | U7: left | V7: -2 | W7: 1 | X7: 1 | Y7: 0.46884492 | AD7: sc1 | AE7: 1 | AF7: 2026-09-09_01h17.37.730 | AG7: staircase task | AI7: 2026.2.3 | AJ7: 59.761224 | AK7: 2026-09-09 01h17.37.783528 +0530
A8: 5 | B8: 2 | C8: 1 | D8: 13.103953 | N8: 13.087513 | O8: 13.103953 | P8: 13.603826 | Q8: 13.587218 | R8: 13.587218 | S8: 13.887227 | T8: 14.253552 | U8: left | V8: -1 | W8: 1 | X8: 1 | Y8: 0.6505215 | AD8: sc1 | AE8: 1 | AF8: 2026-09-09_01h17.37.730 | AG8: staircase task | AI8: 2026.2.3 | AJ8: 59.761224 | AK8: 2026-09-09 01h17.37.783528 +0530
A9: 6 | B9: 1 | C9: 1 | D9: 14.270558 | N9: 14.253585 | O9: 14.270558 | P9: 14.770766 | Q9: 14.753938 | R9: 14.753938 | S9: 15.054054 | T9: 15.170775 | U9: left | V9: -1 | W9: 0 | X9: 0 | Y9: 0.40581867 | AD9: sc1 | AE9: 1 | AF9: 2026-09-09_01h17.37.730 | AG9: staircase task | AI9: 2026.2.3 | AJ9: 59.761224 | AK9: 2026-09-09 01h17.37.783528 +0530
A10: 7 | B10: 1 | C10: 2 | D10: 15.187342 | N10: 15.170802 | O10: 15.187342 | P10: 15.68733 | Q10: 15.670711 | R10: 15.670711 | S10: 15.970674 | T10: 16.070736 | U10: right | V10: 2 | W10: 0 | X10: 0 | Y10: 0.38999967 | AD10: sc1 | AE10: 1 | AF10: 2026-09-09_01h17.37.730 | AG10: staircase task | AI10: 2026.2.3 | AJ10: 59.761224 | AK10: 2026-09-09 01h17.37.783528 +0530
A11: 8 | B11: 1 | C11: 3 | D11: 16.087317 | N11: 16.070763 | O11: 16.087317 | P11: 16.58733 | Q11: 16.570544 | R11: 16.570544 | S11: 16.870665 | T11: 17.270236 | U11: right | V11: 3 | W11: 1 | X11: 1 | Y11: 0.69216054 | AD11: sc1 | AE11: 1 | AF11: 2026-09-09_01h17.37.730 | AG11: staircase task | AI11: 2026.2.3 | AJ11: 59.761224 | AK11: 2026-09-09 01h17.37.783528 +0530
A12: 9 | B12: 1 | C12: 3 | D12: 17.286409 | N12: 17.270264 | O12: 17.286409 | P12: 17.787236 | Q12: 17.770595 | R12: 17.770595 | S12: 18.070532 | T12: 18.33754 | U12: right | V12: 3 | W12: 1 | X12: 1 | Y12: 0.56209054 | AD12: sc1 | AE12: 1 | AF12: 2026-09-09_01h17.37.730 | AG12: staircase task | AI12: 2026.2.3 | AJ12: 59.761224 | AK12: 2026-09-09 01h17.37.783528 +0530
A13: 10 | B13: 1 | C13: 3 | D13: 18.354077 | N13: 18.337562 | O13: 18.354077 | P13: 18.853732 | Q13: 18.837062 | R13: 18.837062 | S13: 19.137316 | T13: 19.286509 | U13: left | V13: -3 | W13: 0 | X13: 0 | Y13: 0.44458992 | AD13: sc1 | AE13: 1 | AF13: 2026-09-09_01h17.37.730 | AG13: staircase task | AI13: 2026.2.3 | AJ13: 59.761224 | AK13: 2026-09-09 01h17.37.783528 +0530
A14: 11 | B14: 1 | C14: 4 | D14: 19.3039 | N14: 19.286552 | O14: 19.3039 | P14: 19.803832 | Q14: 19.787243 | R14: 19.787243 | S14: 20.087332 | T14: 20.403986 | U14: right | V14: 4 | W14: 1 | X14: 1 | Y14: 0.61642225 | AD14: sc1 | AE14: 1 | AF14: 2026-09-09_01h17.37.730 | AG14: staircase task | AI14: 2026.2.3 | AJ14: 59.761224 | AK14: 2026-09-09 01h17.37.783528 +0530
... A102: 99 | B102: 0.5 | C102: 3 | D102: 112.98695 | N102: 112.97064 | O102: 112.98695 | P102: 113.48717 | Q102: 113.47043 | R102: 113.47043 | S102: 113.77035 | T102: 114.13718 | U102: left | V102: -3 | W102: 1 | X102: 1 | Y102: 0.65810304 | AD102: sc1 | AE102: 1 | AF102: 2026-09-09_01h17.37.730 | AG102: staircase task | AI102: 2026.2.3 | AJ102: 59.761224 | AK102: 2026-09-09 01h17.37.783528 +0530
Z103: 114.13721 | AA103: 114.1537 | AB103: 117.15335 | AC103: 117.13711 | AD103: sc1 | AE103: 1 | AF103: 2026-09-09_01h17.37.730 | AG103: staircase task | AI103: 2026.2.3 | AJ103: 59.761224 | AK103: 2026-09-09 01h17.37.783528 +0530

Sheet Analysis
A1: Adaptive Staircase — Difference Threshold Analysis
A3: Trial | B3: Tilt intensity (deg) | C3: Step size | D3: Correct answer | E3: Response | F3: Response correct (1/0) | G3: Is 1-to-0 reversal | H3: Reversal no. | I3: Tilt at reversal (deg)
A4: 1 | B4: 10 | C4: 2 | D4: left | F4: 1 | G4: 0 | H4: =IF(G4=1,SUM($G$4:G4),"") | I4: =IF(G4=1,B4,"")
A5: 2 | B5: 8 | C5: 2 | D5: left | F5: 1 | G5: =IF(AND(F4=1,F5=0),1,0) -> 0 | H5: =IF(G5=1,SUM($G$4:G5),"") | I5: =IF(G5=1,B5,"")
A6: 3 | B6: 6 | C6: 2 | D6: right | F6: 1 | G6: =IF(AND(F5=1,F6=0),1,0) -> 0 | H6: =IF(G6=1,SUM($G$4:G6),"") | I6: =IF(G6=1,B6,"")
A7: 4 | B7: 4 | C7: 2 | D7: right | F7: 1 | G7: =IF(AND(F6=1,F7=0),1,0) -> 0 | H7: =IF(G7=1,SUM($G$4:G7),"") | I7: =IF(G7=1,B7,"")
A8: 5 | B8: 2 | C8: 2 | D8: left | F8: 1 | G8: =IF(AND(F7=1,F8=0),1,0) -> 0 | H8: =IF(G8=1,SUM($G$4:G8),"") | I8: =IF(G8=1,B8,"")
A9: 6 | B9: 1 | C9: 2 | D9: left | F9: 1 | G9: =IF(AND(F8=1,F9=0),1,0) -> 0 | H9: =IF(G9=1,SUM($G$4:G9),"") | I9: =IF(G9=1,B9,"")
A10: 7 | B10: 1 | C10: 1 | D10: left | F10: 0 | G10: =IF(AND(F9=1,F10=0),1,0) -> 1 | H10: =IF(G10=1,SUM($G$4:G10),"") -> 1 | I10: =IF(G10=1,B10,"") -> 1
A11: 8 | B11: 2 | C11: 1 | D11: right | F11: 0 | G11: =IF(AND(F10=1,F11=0),1,0) -> 0 | H11: =IF(G11=1,SUM($G$4:G11),"") | I11: =IF(G11=1,B11,"")
A12: 9 | B12: 3 | C12: 1 | D12: right | F12: 1 | G12: =IF(AND(F11=1,F12=0),1,0) -> 0 | H12: =IF(G12=1,SUM($G$4:G12),"") | I12: =IF(G12=1,B12,"")
A13: 10 | B13: 3 | C13: 1 | D13: right | F13: 1 | G13: =IF(AND(F12=1,F13=0),1,0) -> 0 | H13: =IF(G13=1,SUM($G$4:G13),"") | I13: =IF(G13=1,B13,"")
A14: 11 | B14: 3 | C14: 1 | D14: left | F14: 0 | G14: =IF(AND(F13=1,F14=0),1,0) -> 1 | H14: =IF(G14=1,SUM($G$4:G14),"") -> 2 | I14: =IF(G14=1,B14,"") -> 3
A15: 12 | B15: 4 | C15: 1 | D15: right | F15: 1 | G15: =IF(AND(F14=1,F15=0),1,0) -> 0 | H15: =IF(G15=1,SUM($G$4:G15),"") | I15: =IF(G15=1,B15,"")
A16: 13 | B16: 4 | C16: 1 | D16: left | F16: 1 | G16: =IF(AND(F15=1,F16=0),1,0) -> 0 | H16: =IF(G16=1,SUM($G$4:G16),"") | I16: =IF(G16=1,B16,"")
... A103: 100 | B103: 3 | C103: 0.5 | D103: left | F103: 1 | G103: =IF(AND(F102=1,F103=0),1,0) -> 0 | H103: =IF(G103=1,SUM($G$4:G103),"") | I103: =IF(G103=1,B103,"")
A106: SUMMARY
A107: Total trials | C107: =COUNT(A4:A103) -> 100
A108: Total 1-to-0 reversals | C108: =SUM(G4:G103) -> 14
A109: Overall accuracy | C109: =AVERAGE(F4:F103) -> 0.79
A110: Number correct | C110: =SUM(F4:F103) -> 79
A111: Mean tilt, all trials (deg) | C111: =AVERAGE(B4:B103) -> 2.94
A114: FINAL FIVE 1-TO-0 REVERSALS
A115: Reversal no. | B115: Trial no. | C115: Tilt intensity (deg)
A116: =SUM($G$4:$G$103)-4 -> 10 | B116: =INDEX($A$4:$A$103,MATCH(A116,$H$4:$H$103,0)) -> 68 | C116: =INDEX($B$4:$B$103,MATCH(A116,$H$4:$H$103,0)) -> 1
A117: =SUM($G$4:$G$103)-3 -> 11 | B117: =INDEX($A$4:$A$103,MATCH(A117,$H$4:$H$103,0)) -> 73 | C117: =INDEX($B$4:$B$103,MATCH(A117,$H$4:$H$103,0)) -> 3
A118: =SUM($G$4:$G$103)-2 -> 12 | B118: =INDEX($A$4:$A$103,MATCH(A118,$H$4:$H$103,0)) -> 78 | C118: =INDEX($B$4:$B$103,MATCH(A118,$H$4:$H$103,0)) -> 3.5
A119: =SUM($G$4:$G$103)-1 -> 13 | B119: =INDEX($A$4:$A$103,MATCH(A119,$H$4:$H$103,0)) -> 86 | C119: =INDEX($B$4:$B$103,MATCH(A119,$H$4:$H$103,0)) -> 3
A120: =SUM($G$4:$G$103)-0 -> 14 | B120: =INDEX($A$4:$A$103,MATCH(A120,$H$4:$H$103,0)) -> 95 | C120: =INDEX($B$4:$B$103,MATCH(A120,$H$4:$H$103,0)) -> 3
C122: Mean of final five reversals = | D122: =AVERAGE(C116:C120) -> 2.7
C123: degrees of tilt
A128: CHART DATA - all 1-to-0 reversals
A129: Reversal no. | B129: Trial no. | C129: Tilt (deg)
A130: 1 | B130: =INDEX($A$4:$A$103,MATCH(A130,$H$4:$H$103,0)) -> 7 | C130: =INDEX($B$4:$B$103,MATCH(A130,$H$4:$H$103,0)) -> 1
A131: 2 | B131: =INDEX($A$4:$A$103,MATCH(A131,$H$4:$H$103,0)) -> 11 | C131: =INDEX($B$4:$B$103,MATCH(A131,$H$4:$H$103,0)) -> 3
A132: 3 | B132: =INDEX($A$4:$A$103,MATCH(A132,$H$4:$H$103,0)) -> 17 | C132: =INDEX($B$4:$B$103,MATCH(A132,$H$4:$H$103,0)) -> 3
A133: 4 | B133: =INDEX($A$4:$A$103,MATCH(A133,$H$4:$H$103,0)) -> 26 | C133: =INDEX($B$4:$B$103,MATCH(A133,$H$4:$H$103,0)) -> 3
A134: 5 | B134: =INDEX($A$4:$A$103,MATCH(A134,$H$4:$H$103,0)) -> 37 | C134: =INDEX($B$4:$B$103,MATCH(A134,$H$4:$H$103,0)) -> 2
A135: 6 | B135: =INDEX($A$4:$A$103,MATCH(A135,$H$4:$H$103,0)) -> 43 | C135: =INDEX($B$4:$B$103,MATCH(A135,$H$4:$H$103,0)) -> 2
A136: 7 | B136: =INDEX($A$4:$A$103,MATCH(A136,$H$4:$H$103,0)) -> 48 | C136: =INDEX($B$4:$B$103,MATCH(A136,$H$4:$H$103,0)) -> 2
...

Sheet Graphs
B1: Trial | C1: Tilt | D1: key_resp.corr
B2: 1 | C2: ='Raw Data'!V3 -> -10 | D2: ='Raw Data'!W3 -> 1
B3: 2 | C3: ='Raw Data'!V4 -> -8 | D3: ='Raw Data'!W4 -> 1
B4: 3 | C4: ='Raw Data'!V5 -> 6 | D4: ='Raw Data'!W5 -> 1
B5: 4 | C5: ='Raw Data'!V6 -> 4 | D5: ='Raw Data'!W6 -> 1
B6: 5 | C6: ='Raw Data'!V7 -> -2 | D6: ='Raw Data'!W7 -> 1
B7: 6 | C7: ='Raw Data'!V8 -> -1 | D7: ='Raw Data'!W8 -> 1
B8: 7 | C8: ='Raw Data'!V9 -> -1 | D8: ='Raw Data'!W9 -> 0
B9: 8 | C9: ='Raw Data'!V10 -> 2 | D9: ='Raw Data'!W10 -> 0
B10: 9 | C10: ='Raw Data'!V11 -> 3 | D10: ='Raw Data'!W11 -> 1
B11: 10 | C11: ='Raw Data'!V12 -> 3 | D11: ='Raw Data'!W12 -> 1
B12: 11 | C12: ='Raw Data'!V13 -> -3 | D12: ='Raw Data'!W13 -> 0
B13: 12 | C13: ='Raw Data'!V14 -> 4 | D13: ='Raw Data'!W14 -> 1
... B101: 100 | C101: ='Raw Data'!V102 -> -3 | D101: ='Raw Data'!W102 -> 1
C103: Total correct | D103: =SUM(D2:D101) -> 79
